<sdf version='1.11'>
  <model name='fetch'>
    <link name='base_link'>
      <inertial>
        <pose>-0.02832733619922052 0.00091222075190954574 0.1035345291637047 0 0 0</pose>
        <mass>83.457197650131334</mass>
        <inertia>
          <ixx>10.20842700260733</ixx>
          <ixy>0.021339385609369391</ixy>
          <ixz>1.1094630207152001</ixz>
          <iyy>10.49193504554397</iyy>
          <iyz>-0.032621911837896179</iyz>
          <izz>5.3613977046516306</izz>
        </inertia>
      </inertial>
      <collision name='base_link_collision'>
        <pose>0 0 0 0 0 0</pose>
        <geometry>
          <mesh>
            <scale>1 1 1</scale>
            <uri>model://fetch_description/meshes/base_link_collision.STL</uri>
          </mesh>
        </geometry>
        <surface>
          <contact>
            <ode>
              <kp>100000000</kp>
              <kd>10</kd>
              <max_vel>10</max_vel>
              <min_depth>0.00050000000000000001</min_depth>
            </ode>
          </contact>
          <friction>
            <ode>
              <mu>0.10000000000000001</mu>
              <mu2>0.10000000000000001</mu2>
              <fdir1>1 0 0</fdir1>
            </ode>
          </friction>
        </surface>
      </collision>
      <collision name='base_link_fixed_joint_lump__bl_caster_link_collision_1'>
        <pose>-0.20000000000000001 -0.12 0.055324999999999999 0 0 0</pose>
        <geometry>
          <sphere>
            <radius>0.060100000000000001</radius>
          </sphere>
        </geometry>
        <surface>
          <contact>
            <ode>
              <kp>100000000</kp>
              <kd>10</kd>
              <max_vel>10</max_vel>
              <min_depth>0.001</min_depth>
            </ode>
          </contact>
          <friction>
            <ode>
              <mu>0.10000000000000001</mu>
              <mu2>0.10000000000000001</mu2>
            </ode>
          </friction>
        </surface>
      </collision>
      <collision name='base_link_fixed_joint_lump__br_caster_link_collision_2'>
        <pose>-0.20000000000000001 0.12 0.055324999999999999 0 0 0</pose>
        <geometry>
          <sphere>
            <radius>0.060100000000000001</radius>
          </sphere>
        </geometry>
        <surface>
          <contact>
            <ode>
              <kp>100000000</kp>
              <kd>10</kd>
              <max_vel>10</max_vel>
              <min_depth>0.001</min_depth>
            </ode>
          </contact>
          <friction>
            <ode>
              <mu>0.10000000000000001</mu>
              <mu2>0.10000000000000001</mu2>
            </ode>
          </friction>
        </surface>
      </collision>
      <collision name='base_link_fixed_joint_lump__estop_link_collision_3'>
        <pose>-0.12465 0.23891999999999999 0.31126999999999999 1.5708 0 0</pose>
        <geometry>
          <mesh>
            <scale>1 1 1</scale>
            <uri>model://fetch_description/meshes/estop_link.STL</uri>
          </mesh>
        </geometry>
        <surface>
          <contact>
            <ode/>
          </contact>
          <friction>
            <ode/>
          </friction>
        </surface>
      </collision>
      <collision name='base_link_fixed_joint_lump__fl_caster_link_collision_4'>
        <pose>0.14999999999999999 0.12 0.055324999999999999 0 0 0</pose>
        <geometry>
          <sphere>
            <radius>0.060100000000000001</radius>
          </sphere>
        </geometry>
        <surface>
          <contact>
            <ode>
              <kp>100000000</kp>
              <kd>10</kd>
              <max_vel>10</max_vel>
              <min_depth>0.001</min_depth>
            </ode>
          </contact>
          <friction>
            <ode>
              <mu>0.10000000000000001</mu>
              <mu2>0.10000000000000001</mu2>
            </ode>
          </friction>
        </surface>
      </collision>
      <collision name='base_link_fixed_joint_lump__fr_caster_link_collision_5'>
        <pose>0.14999999999999999 -0.12 0.055324999999999999 0 0 0</pose>
        <geometry>
          <sphere>
            <radius>0.060100000000000001</radius>
          </sphere>
        </geometry>
        <surface>
          <contact>
            <ode>
              <kp>100000000</kp>
              <kd>10</kd>
              <max_vel>10</max_vel>
              <min_depth>0.001</min_depth>
            </ode>
          </contact>
          <friction>
            <ode>
              <mu>0.10000000000000001</mu>
              <mu2>0.10000000000000001</mu2>
            </ode>
          </friction>
        </surface>
      </collision>
      <collision name='base_link_fixed_joint_lump__laser_link_collision_6'>
        <pose>0.23499999999999999 0 0.2878 -3.1415926535895871 0 0</pose>
        <geometry>
          <mesh>
            <scale>1 1 1</scale>
            <uri>model://fetch_description/meshes/laser_link.STL</uri>
          </mesh>
        </geometry>
        <surface>
          <contact>
            <ode/>
          </contact>
          <friction>
            <ode/>
          </friction>
        </surface>
      </collision>
      <collision name='base_link_fixed_joint_lump__torso_fixed_link_collision_7'>
        <pose>-0.086874999999999994 0 0.37742500000000001 -6.12303176911189e-17 0 0</pose>
        <geometry>
          <mesh>
            <scale>1 1 1</scale>
            <uri>model://fetch_description/meshes/torso_fixed_link.STL</uri>
          </mesh>
        </geometry>
      </collision>
      <visual name='base_link_visual'>
        <pose>0 0 0 0 0 0</pose>
        <geometry>
          <mesh>
            <scale>1 1 1</scale>
            <uri>model://fetch_description/meshes/base_link.dae</uri>
          </mesh>
        </geometry>
        <material>
          <diffuse>0.444999993 0.451249987 0.469999969 1</diffuse>
          <ambient>0.444999993 0.451249987 0.469999969 1</ambient>
        </material>
      </visual>
      <visual name='base_link_fixed_joint_lump__bl_caster_link_visual_1'>
        <pose>-0.20000000000000001 -0.12 0.055324999999999999 0 0 0</pose>
        <geometry>
          <sphere>
            <radius>0.060100000000000001</radius>
          </sphere>
        </geometry>
        <material>
          <diffuse>0.107500002 0.632499993 0.95875001 1</diffuse>
          <ambient>0.107500002 0.632499993 0.95875001 1</ambient>
        </material>
      </visual>
      <visual name='base_link_fixed_joint_lump__br_caster_link_visual_2'>
        <pose>-0.20000000000000001 0.12 0.055324999999999999 0 0 0</pose>
        <geometry>
          <sphere>
            <radius>0.060100000000000001</radius>
          </sphere>
        </geometry>
        <material>
          <diffuse>0.107500002 0.632499993 0.95875001 1</diffuse>
          <ambient>0.107500002 0.632499993 0.95875001 1</ambient>
        </material>
      </visual>
      <visual name='base_link_fixed_joint_lump__estop_link_visual_3'>
        <pose>-0.12465 0.23891999999999999 0.31126999999999999 1.5708 0 0</pose>
        <geometry>
          <mesh>
            <scale>1 1 1</scale>
            <uri>model://fetch_description/meshes/estop_link.dae</uri>
          </mesh>
        </geometry>
        <material>
          <script>
            <name>Gazebo/Red</name>
            <uri>file://media/materials/scripts/gazebo.material</uri>
          </script>
          <diffuse>1 0 0 1</diffuse>
          <ambient>1 0 0 1</ambient>
        </material>
      </visual>
      <visual name='base_link_fixed_joint_lump__fl_caster_link_visual_4'>
        <pose>0.14999999999999999 0.12 0.055324999999999999 0 0 0</pose>
        <geometry>
          <sphere>
            <radius>0.060100000000000001</radius>
          </sphere>
        </geometry>
        <material>
          <diffuse>0.107500002 0.632499993 0.95875001 1</diffuse>
          <ambient>0.107500002 0.632499993 0.95875001 1</ambient>
        </material>
      </visual>
      <visual name='base_link_fixed_joint_lump__fr_caster_link_visual_5'>
        <pose>0.14999999999999999 -0.12 0.055324999999999999 0 0 0</pose>
        <geometry>
          <sphere>
            <radius>0.060100000000000001</radius>
          </sphere>
        </geometry>
        <material>
          <diffuse>0.107500002 0.632499993 0.95875001 1</diffuse>
          <ambient>0.107500002 0.632499993 0.95875001 1</ambient>
        </material>
      </visual>
      <visual name='base_link_fixed_joint_lump__laser_link_visual_6'>
        <pose>0.23499999999999999 0 0.2878 -3.1415926535895871 0 0</pose>
        <geometry>
          <mesh>
            <scale>1 1 1</scale>
            <uri>model://fetch_description/meshes/laser_link.STL</uri>
          </mesh>
        </geometry>
        <material>
          <diffuse>0.990196109 1 1 1</diffuse>
          <ambient>0.990196109 1 1 1</ambient>
        </material>
      </visual>
      <visual name='base_link_fixed_joint_lump__torso_fixed_link_visual_7'>
        <pose>-0.086874999999999994 0 0.37742500000000001 -6.12303176911189e-17 0 0</pose>
        <geometry>
          <mesh>
            <scale>1 1 1</scale>
            <uri>model://fetch_description/meshes/torso_fixed_link.dae</uri>
          </mesh>
        </geometry>
        <material>
          <diffuse>0.107500002 0.632499993 0.95875001 1</diffuse>
          <ambient>0.107500002 0.632499993 0.95875001 1</ambient>
        </material>
      </visual>
      <sensor name='base_laser' type='ray'>
        <visualize>false</visualize>
        <update_rate>15</update_rate>
        <ray>
          <scan>
            <horizontal>
              <samples>662</samples>
              <resolution>1</resolution>
              <min_angle>-1.9198599999999999</min_angle>
              <max_angle>1.9198599999999999</max_angle>
            </horizontal>
          </scan>
          <range>
            <min>0.050000000000000003</min>
            <max>25</max>
            <resolution>0.01</resolution>
          </range>
          <noise>
            <type>gaussian</type>
            <mean>0</mean>
            <stddev>0.02</stddev>
          </noise>
        </ray>
        <plugin name='gazebo_ros_base_hokuyo_controller' filename='libgazebo_ros_laser.so'>
          <topicName>/base_scan</topicName>
          <frameName>laser_link</frameName>
        </plugin>
        <pose>0.23499999999999999 0 0.2878 -3.1415899999999999 0 0</pose>
      </sensor>
    </link>
    <joint name='l_wheel_joint' type='revolute'>
      <pose relative_to='base_link'>0.0012914000000000001 0.18737999999999999 0.055324999999999999 -6.1229999999999999e-17 0 0</pose>
      <parent>base_link</parent>
      <child>l_wheel_link</child>
      <axis>
        <xyz>0 1 0</xyz>
        <limit>
          <effort>8.8499999999999996</effort>
          <velocity>17.399999999999999</velocity>
          <lower>-inf</lower>
          <upper>inf</upper>
        </limit>
        <dynamics>
          <spring_reference>0</spring_reference>
          <spring_stiffness>0</spring_stiffness>
        </dynamics>
      </axis>
      <physics>
        <ode>
          <implicit_spring_damper>true</implicit_spring_damper>
          <cfm_damping>true</cfm_damping>
          <limit>
            <cfm>0</cfm>
            <erp>0.20000000000000001</erp>
          </limit>
        </ode>
      </physics>
    </joint>
    <link name='l_wheel_link'>
      <pose relative_to='l_wheel_joint'>0 0 0 0 0 0</pose>
      <inertial>
        <pose>0 0 0 0 0 0</pose>
        <mass>4.3541999999999996</mass>
        <inertia>
          <ixx>0.0044999999999999997</ixx>
          <ixy>0</ixy>
          <ixz>0</ixz>
          <iyy>0.0050000000000000001</iyy>
          <iyz>0</iyz>
          <izz>0.0044999999999999997</izz>
        </inertia>
      </inertial>
      <collision name='l_wheel_link_collision'>
        <pose>0 0 0 0 0 0</pose>
        <geometry>
          <mesh>
            <scale>1 1 1</scale>
            <uri>model://fetch_description/meshes/l_wheel_link_collision.STL</uri>
          </mesh>
        </geometry>
        <surface>
          <contact>
            <ode>
              <kp>1000000</kp>
              <kd>100</kd>
              <max_vel>1</max_vel>
              <min_depth>0.01</min_depth>
            </ode>
          </contact>
          <friction>
            <ode>
              <mu>100000000000000</mu>
              <mu2>100000000000000</mu2>
            </ode>
          </friction>
        </surface>
      </collision>
      <visual name='l_wheel_link_visual'>
        <pose>0 0 0 0 0 0</pose>
        <geometry>
          <mesh>
            <scale>1 1 1</scale>
            <uri>model://fetch_description/meshes/l_wheel_link.STL</uri>
          </mesh>
        </geometry>
        <material>
          <script>
            <name>Gazebo/Black</name>
            <uri>file://media/materials/scripts/gazebo.material</uri>
          </script>
          <diffuse>0.107500002 0.632499993 0.95875001 1</diffuse>
          <ambient>0.107500002 0.632499993 0.95875001 1</ambient>
        </material>
      </visual>
    </link>
    <joint name='r_wheel_joint' type='revolute'>
      <pose relative_to='base_link'>0.0012914000000000001 -0.18737999999999999 0.055324999999999999 -6.1229999999999999e-17 0 0</pose>
      <parent>base_link</parent>
      <child>r_wheel_link</child>
      <axis>
        <xyz>0 1 0</xyz>
        <limit>
          <effort>8.8499999999999996</effort>
          <velocity>17.399999999999999</velocity>
          <lower>-inf</lower>
          <upper>inf</upper>
        </limit>
        <dynamics>
          <spring_reference>0</spring_reference>
          <spring_stiffness>0</spring_stiffness>
        </dynamics>
      </axis>
      <physics>
        <ode>
          <implicit_spring_damper>true</implicit_spring_damper>
          <cfm_damping>true</cfm_damping>
          <limit>
            <cfm>0</cfm>
            <erp>0.20000000000000001</erp>
          </limit>
        </ode>
      </physics>
    </joint>
    <link name='r_wheel_link'>
      <pose relative_to='r_wheel_joint'>0 0 0 0 0 0</pose>
      <inertial>
        <pose>0 0 0 0 0 0</pose>
        <mass>4.3541999999999996</mass>
        <inertia>
          <ixx>0.0044999999999999997</ixx>
          <ixy>0</ixy>
          <ixz>0</ixz>
          <iyy>0.0050000000000000001</iyy>
          <iyz>0</iyz>
          <izz>0.0044999999999999997</izz>
        </inertia>
      </inertial>
      <collision name='r_wheel_link_collision'>
        <pose>0 0 0 0 0 0</pose>
        <geometry>
          <mesh>
            <scale>1 1 1</scale>
            <uri>model://fetch_description/meshes/r_wheel_link_collision.STL</uri>
          </mesh>
        </geometry>
        <surface>
          <contact>
            <ode>
              <kp>1000000</kp>
              <kd>100</kd>
              <max_vel>1</max_vel>
              <min_depth>0.01</min_depth>
            </ode>
          </contact>
          <friction>
            <ode>
              <mu>100000000000000</mu>
              <mu2>100000000000000</mu2>
            </ode>
          </friction>
        </surface>
      </collision>
      <visual name='r_wheel_link_visual'>
        <pose>0 0 0 0 0 0</pose>
        <geometry>
          <mesh>
            <scale>1 1 1</scale>
            <uri>model://fetch_description/meshes/r_wheel_link.STL</uri>
          </mesh>
        </geometry>
        <material>
          <script>
            <name>Gazebo/Black</name>
            <uri>file://media/materials/scripts/gazebo.material</uri>
          </script>
          <diffuse>0.107500002 0.632499993 0.95875001 1</diffuse>
          <ambient>0.107500002 0.632499993 0.95875001 1</ambient>
        </material>
      </visual>
    </link>
    <joint name='torso_lift_joint' type='prismatic'>
      <pose relative_to='base_link'>-0.086874999999999994 0 0.37742999999999999 -6.1229999999999999e-17 0 0</pose>
      <parent>base_link</parent>
      <child>torso_lift_link</child>
      <axis>
        <xyz>0 0 1</xyz>
        <limit>
          <lower>0</lower>
          <upper>0.38614999999999999</upper>
          <effort>450</effort>
          <velocity>0.10000000000000001</velocity>
        </limit>
        <dynamics>
          <damping>100</damping>
          <friction>0</friction>
          <spring_reference>0</spring_reference>
          <spring_stiffness>0</spring_stiffness>
        </dynamics>
      </axis>
    </joint>
    <link name='torso_lift_link'>
      <pose relative_to='torso_lift_joint'>0 0 0 0 0 0</pose>
      <inertial>
        <pose>-0.00098392925751669322 -0.00088607754170730096 0.28687350348396728 0 0 0</pose>
        <mass>10.948974038216599</mass>
        <inertia>
          <ixx>0.36931001784810918</ixx>
          <ixy>-3.0664045581140989e-06</ixy>
          <ixz>-0.014740576039134329</ixz>
          <iyy>0.36781237861547461</iyy>
          <iyz>-0.00053571211634028922</iyz>
          <izz>0.097163924949691713</izz>
        </inertia>
      </inertial>
      <collision name='torso_lift_link_collision'>
        <pose>0 0 0 0 0 0</pose>
        <geometry>
          <mesh>
            <scale>1 1 1</scale>
            <uri>model://fetch_description/meshes/torso_lift_link_collision.STL</uri>
          </mesh>
        </geometry>
      </collision>
      <collision name='torso_lift_link_fixed_joint_lump__bellows_link2_collision_1'>
        <pose>0 0 0 0 0 0</pose>
        <geometry>
          <mesh>
            <scale>1 1 1</scale>
            <uri>model://fetch_description/meshes/bellows_link_collision.STL</uri>
          </mesh>
        </geometry>
        <surface>
          <contact>
            <ode/>
          </contact>
          <friction>
            <ode/>
          </friction>
        </surface>
      </collision>
      <visual name='torso_lift_link_visual'>
        <pose>0 0 0 0 0 0</pose>
        <geometry>
          <mesh>
            <scale>1 1 1</scale>
            <uri>model://fetch_description/meshes/torso_lift_link.dae</uri>
          </mesh>
        </geometry>
        <material>
          <diffuse>1 1 1 1</diffuse>
          <ambient>1 1 1 1</ambient>
        </material>
      </visual>
      <visual name='torso_lift_link_fixed_joint_lump__bellows_link2_visual_1'>
        <pose>0 0 0 0 0 0</pose>
        <geometry>
          <mesh>
            <scale>1 1 1</scale>
            <uri>model://fetch_description/meshes/bellows_link.STL</uri>
          </mesh>
        </geometry>
        <material>
          <script>
            <name>Gazebo/Black</name>
            <uri>file://media/materials/scripts/gazebo.material</uri>
          </script>
          <diffuse>0 0 0 1</diffuse>
          <ambient>0 0 0 1</ambient>
        </material>
      </visual>
    </link>
    <joint name='bellows_joint' type='prismatic'>
      <pose relative_to='torso_lift_link'>0 0 0 0 0 0</pose>
      <parent>torso_lift_link</parent>
      <child>bellows_link</child>
      <axis>
        <xyz>0 0 -1</xyz>
        <limit>
          <lower>0</lower>
          <upper>0.40000000000000002</upper>
          <effort>5</effort>
          <velocity>0.10000000000000001</velocity>
        </limit>
        <dynamics>
          <spring_reference>0</spring_reference>
          <spring_stiffness>0</spring_stiffness>
        </dynamics>
      </axis>
    </joint>
    <link name='bellows_link'>
      <pose relative_to='bellows_joint'>0 0 0 0 0 0</pose>
      <inertial>
        <pose>0.019132000028622798 -1.6721987348131499e-16 -0.13486162544338701 0 0 0</pose>
        <mass>0.16937403821660199</mass>
        <inertia>
          <ixx>0.00331159128762117</ixx>
          <ixy>-8.9230964321454999e-18</ixy>
          <ixz>-5.3862220101829302e-08</ixz>
          <iyy>0.0017444729278662701</iyy>
          <iyz>-8.06964979976371e-17</iyz>
          <izz>0.00169417568121457</izz>
        </inertia>
      </inertial>
      <collision name='bellows_link_collision'>
        <pose>0 0 0 0 0 0</pose>
        <geometry>
          <mesh>
            <scale>1 1 1</scale>
            <uri>model://fetch_description/meshes/bellows_link_collision.STL</uri>
          </mesh>
        </geometry>
        <surface>
          <contact>
            <ode/>
          </contact>
          <friction>
            <ode/>
          </friction>
        </surface>
      </collision>
      <visual name='bellows_link_visual'>
        <pose>0 0 0 0 0 0</pose>
        <geometry>
          <mesh>
            <scale>1 1 1</scale>
            <uri>model://fetch_description/meshes/bellows_link.STL</uri>
          </mesh>
        </geometry>
        <material>
          <script>
            <name>Gazebo/Black</name>
            <uri>file://media/materials/scripts/gazebo.material</uri>
          </script>
          <diffuse>0 0 0 1</diffuse>
          <ambient>0 0 0 1</ambient>
        </material>
      </visual>
    </link>
    <joint name='head_pan_joint' type='revolute'>
      <pose relative_to='torso_lift_link'>0.053124999999999999 0 0.603001417713939 0 0 0</pose>
      <parent>torso_lift_link</parent>
      <child>head_pan_link</child>
      <axis>
        <xyz>0 0 1</xyz>
        <limit>
          <lower>-1.5700000000000001</lower>
          <upper>1.5700000000000001</upper>
          <effort>0.32000000000000001</effort>
          <velocity>1.5700000000000001</velocity>
        </limit>
        <dynamics>
          <spring_reference>0</spring_reference>
          <spring_stiffness>0</spring_stiffness>
        </dynamics>
      </axis>
    </joint>
    <link name='head_pan_link'>
      <pose relative_to='head_pan_joint'>0 0 0 0 0 0</pose>
      <inertial>
        <pose>0.032099999999999997 0.0161 0.039 0 0 0</pose>
        <mass>2.2555999999999998</mass>
        <inertia>
          <ixx>0.0129</ixx>
          <ixy>0.00020000000000000001</ixy>
          <ixz>0.00069999999999999999</ixz>
          <iyy>0.0094999999999999998</iyy>
          <iyz>0</iyz>
          <izz>0.0184</izz>
        </inertia>
      </inertial>
      <collision name='head_pan_link_collision'>
        <pose>0 0 0 0 0 0</pose>
        <geometry>
          <mesh>
            <scale>1 1 1</scale>
            <uri>model://fetch_description/meshes/head_pan_link_collision.STL</uri>
          </mesh>
        </geometry>
      </collision>
      <visual name='head_pan_link_visual'>
        <pose>0 0 0 0 0 0</pose>
        <geometry>
          <mesh>
            <scale>1 1 1</scale>
            <uri>model://fetch_description/meshes/head_pan_link.dae</uri>
          </mesh>
        </geometry>
        <material>
          <diffuse>0.444999993 0.451249987 0.469999969 1</diffuse>
          <ambient>0.444999993 0.451249987 0.469999969 1</ambient>
        </material>
      </visual>
    </link>
    <joint name='head_tilt_joint' type='revolute'>
      <pose relative_to='head_pan_link'>0.14252999999999999 0 0.057999000000000002 0 0 0</pose>
      <parent>head_pan_link</parent>
      <child>head_tilt_link</child>
      <axis>
        <xyz>0 1 0</xyz>
        <limit>
          <lower>-0.76000000000000001</lower>
          <upper>1.45</upper>
          <effort>0.68000000000000005</effort>
          <velocity>1.5700000000000001</velocity>
        </limit>
        <dynamics>
          <spring_reference>0</spring_reference>
          <spring_stiffness>0</spring_stiffness>
        </dynamics>
      </axis>
    </joint>
    <link name='head_tilt_link'>
      <pose relative_to='head_tilt_joint'>0 0 0 0 0 0</pose>
      <inertial>
        <pose>0.0080999999999999996 0.0025000000000000001 0.011299999999999999 0 0 0</pose>
        <mass>0.90869999999999995</mass>
        <inertia>
          <ixx>0.0061000000000000004</ixx>
          <ixy>0</ixy>
          <ixz>0.00020000000000000001</ixz>
          <iyy>0.0014</iyy>
          <iyz>-0.0001</iyz>
          <izz>0.0061000000000000004</izz>
        </inertia>
      </inertial>
      <collision name='head_tilt_link_collision'>
        <pose>0 0 0 0 0 0</pose>
        <geometry>
          <mesh>
            <scale>1 1 1</scale>
            <uri>model://fetch_description/meshes/head_tilt_link_collision.STL</uri>
          </mesh>
        </geometry>
      </collision>
      <visual name='head_tilt_link_visual'>
        <pose>0 0 0 0 0 0</pose>
        <geometry>
          <mesh>
            <scale>1 1 1</scale>
            <uri>model://fetch_description/meshes/head_tilt_link.dae</uri>
          </mesh>
        </geometry>
        <material>
          <diffuse>0.107500002 0.632499993 0.95875001 1</diffuse>
          <ambient>0.107500002 0.632499993 0.95875001 1</ambient>
        </material>
      </visual>
      <sensor name='camera' type='depth'>
        <always_on>true</always_on>
        <update_rate>15</update_rate>
        <camera>
          <horizontal_fov>1.0471969999999999</horizontal_fov>
          <image>
            <format>B8G8R8</format>
            <width>640</width>
            <height>480</height>
          </image>
          <clip>
            <near>0.050000000000000003</near>
            <far>50</far>
          </clip>
        </camera>
        <plugin name='head_camera_controller' filename='libgazebo_ros_openni_kinect.so'>
          <baseline>0.1</baseline>
          <alwaysOn>true</alwaysOn>
          <updateRate>15.0</updateRate>
          <cameraName>head_camera</cameraName>
          <imageTopicName>/head_camera/rgb/image_raw</imageTopicName>
          <cameraInfoTopicName>/head_camera/rgb/camera_info</cameraInfoTopicName>
          <depthImageTopicName>/head_camera/depth_registered/image_raw</depthImageTopicName>
          <depthImageCameraInfoTopicName>/head_camera/depth_registered/camera_info</depthImageCameraInfoTopicName>
          <pointCloudTopicName>/head_camera/depth_registered/points</pointCloudTopicName>
          <frameName>head_camera_rgb_optical_frame</frameName>
          <pointCloudCutoff>0.35</pointCloudCutoff>
          <pointCloudCutoffMax>4.5</pointCloudCutoffMax>
          <CxPrime>0</CxPrime>
          <Cx>0</Cx>
          <Cy>0</Cy>
          <focalLength>0</focalLength>
          <hackBaseline>0</hackBaseline>
        </plugin>
        <pose>0.055 0.02 0.022499999999999999 0 0 0</pose>
      </sensor>
    </link>
    <joint name='shoulder_pan_joint' type='revolute'>
      <pose relative_to='torso_lift_link'>0.11952500000000001 0 0.34858 0 0 0</pose>
      <parent>torso_lift_link</parent>
      <child>shoulder_pan_link</child>
      <axis>
        <xyz>0 0 1</xyz>
        <limit>
          <lower>-1.6055999999999999</lower>
          <upper>1.6055999999999999</upper>
          <effort>33.82</effort>
          <velocity>1.256</velocity>
        </limit>
        <dynamics>
          <damping>1</damping>
          <friction>0</friction>
          <spring_reference>0</spring_reference>
          <spring_stiffness>0</spring_stiffness>
        </dynamics>
      </axis>
    </joint>
    <link name='shoulder_pan_link'>
      <pose relative_to='shoulder_pan_joint'>0 0 0 0 0 0</pose>
      <inertial>
        <pose>0.092700000000000005 -0.0055999999999999999 0.056399999999999999 0 0 0</pose>
        <mass>2.5587</mass>
        <inertia>
          <ixx>0.0043</ixx>
          <ixy>-0.0001</ixy>
          <ixz>0.001</ixz>
          <iyy>0.0086999999999999994</iyy>
          <iyz>-0.0001</iyz>
          <izz>0.0086999999999999994</izz>
        </inertia>
      </inertial>
      <collision name='shoulder_pan_link_collision'>
        <pose>0 0 0 0 0 0</pose>
        <geometry>
          <mesh>
            <scale>1 1 1</scale>
            <uri>model://fetch_description/meshes/shoulder_pan_link_collision.STL</uri>
          </mesh>
        </geometry>
      </collision>
      <visual name='shoulder_pan_link_visual'>
        <pose>0 0 0 0 0 0</pose>
        <geometry>
          <mesh>
            <scale>1 1 1</scale>
            <uri>model://fetch_description/meshes/shoulder_pan_link.dae</uri>
          </mesh>
        </geometry>
        <material>
          <diffuse>1 1 1 1</diffuse>
          <ambient>1 1 1 1</ambient>
        </material>
      </visual>
    </link>
    <joint name='shoulder_lift_joint' type='revolute'>
      <pose relative_to='shoulder_pan_link'>0.11700000000000001 0 0.059999999999999901 0 0 0</pose>
      <parent>shoulder_pan_link</parent>
      <child>shoulder_lift_link</child>
      <axis>
        <xyz>0 1 0</xyz>
        <limit>
          <lower>-1.2210000000000001</lower>
          <upper>1.518</upper>
          <effort>131.75999999999999</effort>
          <velocity>1.454</velocity>
        </limit>
        <dynamics>
          <damping>1</damping>
          <friction>0</friction>
          <spring_reference>0</spring_reference>
          <spring_stiffness>0</spring_stiffness>
        </dynamics>
      </axis>
    </joint>
    <link name='shoulder_lift_link'>
      <pose relative_to='shoulder_lift_joint'>0 0 0 0 0 0</pose>
      <inertial>
        <pose>0.14319999999999999 0.0071999999999999998 -0.0001 0 0 0</pose>
        <mass>2.6615000000000002</mass>
        <inertia>
          <ixx>0.0028</ixx>
          <ixy>-0.0020999999999999999</ixy>
          <ixz>0</ixz>
          <iyy>0.0111</iyy>
          <iyz>0</iyz>
          <izz>0.0112</izz>
        </inertia>
      </inertial>
      <collision name='shoulder_lift_link_collision'>
        <pose>0 0 0 0 0 0</pose>
        <geometry>
          <mesh>
            <scale>1 1 1</scale>
            <uri>model://fetch_description/meshes/shoulder_lift_link_collision.STL</uri>
          </mesh>
        </geometry>
      </collision>
      <visual name='shoulder_lift_link_visual'>
        <pose>0 0 0 0 0 0</pose>
        <geometry>
          <mesh>
            <scale>1 1 1</scale>
            <uri>model://fetch_description/meshes/shoulder_lift_link.dae</uri>
          </mesh>
        </geometry>
        <material>
          <diffuse>0.107500002 0.632499993 0.95875001 1</diffuse>
          <ambient>0.107500002 0.632499993 0.95875001 1</ambient>
        </material>
      </visual>
    </link>
    <joint name='upperarm_roll_joint' type='revolute'>
      <pose relative_to='shoulder_lift_link'>0.219 0 0 0 0 0</pose>
      <parent>shoulder_lift_link</parent>
      <child>upperarm_roll_link</child>
      <axis>
        <xyz>1 0 0</xyz>
        <limit>
          <effort>76.939999999999998</effort>
          <velocity>1.571</velocity>
          <lower>-inf</lower>
          <upper>inf</upper>
        </limit>
        <dynamics>
          <damping>5</damping>
          <friction>0</friction>
          <spring_reference>0</spring_reference>
          <spring_stiffness>0</spring_stiffness>
        </dynamics>
      </axis>
    </joint>
    <link name='upperarm_roll_link'>
      <pose relative_to='upperarm_roll_joint'>0 0 0 0 0 0</pose>
      <inertial>
        <pose>0.11650000000000001 0.0014 0 0 0 0</pose>
        <mass>2.3311000000000002</mass>
        <inertia>
          <ixx>0.0019</ixx>
          <ixy>-0.0001</ixy>
          <ixz>0</ixz>
          <iyy>0.0044999999999999997</iyy>
          <iyz>0</iyz>
          <izz>0.0047000000000000002</izz>
        </inertia>
      </inertial>
      <collision name='upperarm_roll_link_collision'>
        <pose>0 0 0 0 0 0</pose>
        <geometry>
          <mesh>
            <scale>1 1 1</scale>
            <uri>model://fetch_description/meshes/upperarm_roll_link_collision.STL</uri>
          </mesh>
        </geometry>
      </collision>
      <visual name='upperarm_roll_link_visual'>
        <pose>0 0 0 0 0 0</pose>
        <geometry>
          <mesh>
            <scale>1 1 1</scale>
            <uri>model://fetch_description/meshes/upperarm_roll_link.dae</uri>
          </mesh>
        </geometry>
        <material>
          <diffuse>1 1 1 1</diffuse>
          <ambient>1 1 1 1</ambient>
        </material>
      </visual>
    </link>
    <joint name='elbow_flex_joint' type='revolute'>
      <pose relative_to='upperarm_roll_link'>0.13300000000000001 0 0 0 0 0</pose>
      <parent>upperarm_roll_link</parent>
      <child>elbow_flex_link</child>
      <axis>
        <xyz>0 1 0</xyz>
        <limit>
          <lower>-2.2509999999999999</lower>
          <upper>2.2509999999999999</upper>
          <effort>66.180000000000007</effort>
          <velocity>1.5209999999999999</velocity>
        </limit>
        <dynamics>
          <damping>1</damping>
          <friction>0</friction>
          <spring_reference>0</spring_reference>
          <spring_stiffness>0</spring_stiffness>
        </dynamics>
      </axis>
    </joint>
    <link name='elbow_flex_link'>
      <pose relative_to='elbow_flex_joint'>0 0 0 0 0 0</pose>
      <inertial>
        <pose>0.12790000000000001 0.0073000000000000001 0 0 0 0</pose>
        <mass>2.1299000000000001</mass>
        <inertia>
          <ixx>0.0023999999999999998</ixx>
          <ixy>-0.0016000000000000001</ixy>
          <ixz>0</ixz>
          <iyy>0.0082000000000000007</iyy>
          <iyz>0</iyz>
          <izz>0.0083999999999999995</izz>
        </inertia>
      </inertial>
      <collision name='elbow_flex_link_collision'>
        <pose>0 0 0 0 0 0</pose>
        <geometry>
          <mesh>
            <scale>1 1 1</scale>
            <uri>model://fetch_description/meshes/elbow_flex_link_collision.STL</uri>
          </mesh>
        </geometry>
      </collision>
      <visual name='elbow_flex_link_visual'>
        <pose>0 0 0 0 0 0</pose>
        <geometry>
          <mesh>
            <scale>1 1 1</scale>
            <uri>model://fetch_description/meshes/elbow_flex_link.dae</uri>
          </mesh>
        </geometry>
        <material>
          <diffuse>0.107500002 0.632499993 0.95875001 1</diffuse>
          <ambient>0.107500002 0.632499993 0.95875001 1</ambient>
        </material>
      </visual>
    </link>
    <joint name='forearm_roll_joint' type='revolute'>
      <pose relative_to='elbow_flex_link'>0.19700000000000001 0 0 0 0 0</pose>
      <parent>elbow_flex_link</parent>
      <child>forearm_roll_link</child>
      <axis>
        <xyz>1 0 0</xyz>
        <limit>
          <effort>29.350000000000001</effort>
          <velocity>1.571</velocity>
          <lower>-inf</lower>
          <upper>inf</upper>
        </limit>
        <dynamics>
          <damping>5</damping>
          <friction>0</friction>
          <spring_reference>0</spring_reference>
          <spring_stiffness>0</spring_stiffness>
        </dynamics>
      </axis>
      <physics>
        <ode>
          <implicit_spring_damper>true</implicit_spring_damper>
          <cfm_damping>true</cfm_damping>
          <limit>
            <cfm>0</cfm>
            <erp>0.20000000000000001</erp>
          </limit>
        </ode>
      </physics>
    </joint>
    <link name='forearm_roll_link'>
      <pose relative_to='forearm_roll_joint'>0 0 0 0 0 0</pose>
      <inertial>
        <pose>0.10970000000000001 -0.026599999999999999 0 0 0 0</pose>
        <mass>1.6563000000000001</mass>
        <inertia>
          <ixx>0.0016000000000000001</ixx>
          <ixy>-0.00029999999999999997</ixy>
          <ixz>0</ixz>
          <iyy>0.0030000000000000001</iyy>
          <iyz>0</iyz>
          <izz>0.0035000000000000001</izz>
        </inertia>
      </inertial>
      <collision name='forearm_roll_link_collision'>
        <pose>0 0 0 0 0 0</pose>
        <geometry>
          <mesh>
            <scale>1 1 1</scale>
            <uri>model://fetch_description/meshes/forearm_roll_link_collision.STL</uri>
          </mesh>
        </geometry>
      </collision>
      <visual name='forearm_roll_link_visual'>
        <pose>0 0 0 0 0 0</pose>
        <geometry>
          <mesh>
            <scale>1 1 1</scale>
            <uri>model://fetch_description/meshes/forearm_roll_link.dae</uri>
          </mesh>
        </geometry>
        <material>
          <diffuse>1 1 1 1</diffuse>
          <ambient>1 1 1 1</ambient>
        </material>
      </visual>
    </link>
    <joint name='wrist_flex_joint' type='revolute'>
      <pose relative_to='forearm_roll_link'>0.1245 0 0 0 0 0</pose>
      <parent>forearm_roll_link</parent>
      <child>wrist_flex_link</child>
      <axis>
        <xyz>0 1 0</xyz>
        <limit>
          <lower>-2.1600000000000001</lower>
          <upper>2.1600000000000001</upper>
          <effort>25.699999999999999</effort>
          <velocity>2.2679999999999998</velocity>
        </limit>
        <dynamics>
          <damping>1</damping>
          <friction>0</friction>
          <spring_reference>0</spring_reference>
          <spring_stiffness>0</spring_stiffness>
        </dynamics>
      </axis>
    </joint>
    <link name='wrist_flex_link'>
      <pose relative_to='wrist_flex_joint'>0 0 0 0 0 0</pose>
      <inertial>
        <pose>0.088200000000000001 0.00089999999999999998 -0.0001 0 0 0</pose>
        <mass>1.7250000000000001</mass>
        <inertia>
          <ixx>0.0018</ixx>
          <ixy>-0.0001</ixy>
          <ixz>0</ixz>
          <iyy>0.0041999999999999997</iyy>
          <iyz>0</iyz>
          <izz>0.0041999999999999997</izz>
        </inertia>
      </inertial>
      <collision name='wrist_flex_link_collision'>
        <pose>0 0 0 0 0 0</pose>
        <geometry>
          <mesh>
            <scale>1 1 1</scale>
            <uri>model://fetch_description/meshes/wrist_flex_link_collision.STL</uri>
          </mesh>
        </geometry>
      </collision>
      <visual name='wrist_flex_link_visual'>
        <pose>0 0 0 0 0 0</pose>
        <geometry>
          <mesh>
            <scale>1 1 1</scale>
            <uri>model://fetch_description/meshes/wrist_flex_link.dae</uri>
          </mesh>
        </geometry>
        <material>
          <diffuse>0.107500002 0.632499993 0.95875001 1</diffuse>
          <ambient>0.107500002 0.632499993 0.95875001 1</ambient>
        </material>
      </visual>
    </link>
    <joint name='wrist_roll_joint' type='revolute'>
      <pose relative_to='wrist_flex_link'>0.13850000000000001 0 0 0 0 0</pose>
      <parent>wrist_flex_link</parent>
      <child>wrist_roll_link</child>
      <axis>
        <xyz>1 0 0</xyz>
        <limit>
          <effort>7.3600000000000003</effort>
          <velocity>2.2679999999999998</velocity>
          <lower>-inf</lower>
          <upper>inf</upper>
        </limit>
        <dynamics>
          <damping>5</damping>
          <friction>0</friction>
          <spring_reference>0</spring_reference>
          <spring_stiffness>0</spring_stiffness>
        </dynamics>
      </axis>
      <physics>
        <ode>
          <implicit_spring_damper>true</implicit_spring_damper>
          <cfm_damping>true</cfm_damping>
          <limit>
            <cfm>0</cfm>
            <erp>0.20000000000000001</erp>
          </limit>
        </ode>
      </physics>
    </joint>
    <link name='wrist_roll_link'>
      <pose relative_to='wrist_roll_joint'>0 0 0 0 0 0</pose>
      <inertial>
        <pose>0.070965681529433111 -5.9041684312420598e-05 -0.001577125052937262 0 0 0</pose>
        <mass>1.6529</mass>
        <inertia>
          <ixx>0.0014003107712202789</ixx>
          <ixy>4.1612266395426227e-06</ixy>
          <ixz>1.2483679918627839e-05</ixz>
          <iyy>0.0025574679411330091</iyy>
          <iyz>-9.3231366083852636e-08</iyz>
          <izz>0.0030572193241567851</izz>
        </inertia>
      </inertial>
      <collision name='wrist_roll_link_collision'>
        <pose>0 0 0 0 0 0</pose>
        <geometry>
          <mesh>
            <scale>1 1 1</scale>
            <uri>model://fetch_description/meshes/wrist_roll_link_collision.STL</uri>
          </mesh>
        </geometry>
      </collision>
      <collision name='wrist_roll_link_fixed_joint_lump__gripper_link_collision_1'>
        <pose>0.16644999999999999 0 0 0 0 0</pose>
        <geometry>
          <mesh>
            <scale>1 1 1</scale>
            <uri>model://fetch_description/meshes/gripper_link.STL</uri>
          </mesh>
        </geometry>
      </collision>
      <visual name='wrist_roll_link_visual'>
        <pose>0 0 0 0 0 0</pose>
        <geometry>
          <mesh>
            <scale>1 1 1</scale>
            <uri>model://fetch_description/meshes/wrist_roll_link.dae</uri>
          </mesh>
        </geometry>
        <material>
          <diffuse>1 1 1 1</diffuse>
          <ambient>1 1 1 1</ambient>
        </material>
      </visual>
      <visual name='wrist_roll_link_fixed_joint_lump__gripper_link_visual_1'>
        <pose>0.16644999999999999 0 0 0 0 0</pose>
        <geometry>
          <mesh>
            <scale>1 1 1</scale>
            <uri>model://fetch_description/meshes/gripper_link.dae</uri>
          </mesh>
        </geometry>
      </visual>
    </link>
    <joint name='l_gripper_finger_joint' type='prismatic'>
      <pose relative_to='wrist_roll_link'>0.16644999999999999 -0.015424999999999999 0 0 0 0</pose>
      <parent>wrist_roll_link</parent>
      <child>l_gripper_finger_link</child>
      <axis>
        <xyz>0 -1 0</xyz>
        <limit>
          <lower>0</lower>
          <upper>0.050000000000000003</upper>
          <effort>60</effort>
          <velocity>0.050000000000000003</velocity>
        </limit>
        <dynamics>
          <damping>100</damping>
          <friction>0</friction>
          <spring_reference>0</spring_reference>
          <spring_stiffness>0</spring_stiffness>
        </dynamics>
      </axis>
    </joint>
    <link name='l_gripper_finger_link'>
      <pose relative_to='l_gripper_finger_joint'>0 0 0 0 0 0</pose>
      <inertial>
        <pose>-0.01 0 0 0 0 0</pose>
        <mass>0.079799999999999996</mass>
        <inertia>
          <ixx>0.002</ixx>
          <ixy>0</ixy>
          <ixz>0</ixz>
          <iyy>0</iyy>
          <iyz>0</iyz>
          <izz>0</izz>
        </inertia>
      </inertial>
      <collision name='l_gripper_finger_link_collision'>
        <pose>0 -0.101425 0 0 0 0</pose>
        <geometry>
          <mesh>
            <scale>1 1 1</scale>
            <uri>model://fetch_description/meshes/l_gripper_finger_link.STL</uri>
          </mesh>
        </geometry>
        <surface>
          <contact>
            <ode>
              <kp>1000000</kp>
              <kd>100</kd>
              <max_vel>1</max_vel>
              <min_depth>0.001</min_depth>
            </ode>
          </contact>
          <friction>
            <ode>
              <mu>30</mu>
              <mu2>30</mu2>
            </ode>
          </friction>
        </surface>
      </collision>
      <visual name='l_gripper_finger_link_visual'>
        <pose>0 -0.101425 0 0 0 0</pose>
        <geometry>
          <mesh>
            <scale>1 1 1</scale>
            <uri>model://fetch_description/meshes/l_gripper_finger_link.STL</uri>
          </mesh>
        </geometry>
        <material>
          <script>
            <name>Gazebo/Grey</name>
            <uri>file://media/materials/scripts/gazebo.material</uri>
          </script>
          <diffuse>0.444999993 0.451249987 0.469999969 1</diffuse>
          <ambient>0.444999993 0.451249987 0.469999969 1</ambient>
        </material>
      </visual>
    </link>
    <joint name='r_gripper_finger_joint' type='prismatic'>
      <pose relative_to='wrist_roll_link'>0.16644999999999999 0.015424999999999999 0 0 0 0</pose>
      <parent>wrist_roll_link</parent>
      <child>r_gripper_finger_link</child>
      <axis>
        <xyz>0 1 0</xyz>
        <limit>
          <lower>0</lower>
          <upper>0.050000000000000003</upper>
          <effort>60</effort>
          <velocity>0.050000000000000003</velocity>
        </limit>
        <dynamics>
          <damping>100</damping>
          <friction>0</friction>
          <spring_reference>0</spring_reference>
          <spring_stiffness>0</spring_stiffness>
        </dynamics>
      </axis>
    </joint>
    <link name='r_gripper_finger_link'>
      <pose relative_to='r_gripper_finger_joint'>0 0 0 0 0 0</pose>
      <inertial>
        <pose>-0.01 0 0 0 0 0</pose>
        <mass>0.079799999999999996</mass>
        <inertia>
          <ixx>0.002</ixx>
          <ixy>0</ixy>
          <ixz>0</ixz>
          <iyy>0</iyy>
          <iyz>0</iyz>
          <izz>0</izz>
        </inertia>
      </inertial>
      <collision name='r_gripper_finger_link_collision'>
        <pose>0 0.101425 0 0 0 0</pose>
        <geometry>
          <mesh>
            <scale>1 1 1</scale>
            <uri>model://fetch_description/meshes/r_gripper_finger_link.STL</uri>
          </mesh>
        </geometry>
        <surface>
          <contact>
            <ode>
              <kp>1000000</kp>
              <kd>100</kd>
              <max_vel>1</max_vel>
              <min_depth>0.001</min_depth>
            </ode>
          </contact>
          <friction>
            <ode>
              <mu>30</mu>
              <mu2>30</mu2>
            </ode>
          </friction>
        </surface>
      </collision>
      <visual name='r_gripper_finger_link_visual'>
        <pose>0 0.101425 0 0 0 0</pose>
        <geometry>
          <mesh>
            <scale>1 1 1</scale>
            <uri>model://fetch_description/meshes/r_gripper_finger_link.STL</uri>
          </mesh>
        </geometry>
        <material>
          <script>
            <name>Gazebo/Grey</name>
            <uri>file://media/materials/scripts/gazebo.material</uri>
          </script>
          <diffuse>0.444999993 0.451249987 0.469999969 1</diffuse>
          <ambient>0.444999993 0.451249987 0.469999969 1</ambient>
        </material>
      </visual>
    </link>
    <plugin name='fetch_gazebo_plugin' filename='libfetch_gazebo_plugin.so'/>
    <frame name='bl_caster_joint' attached_to='base_link'>
      <pose>-0.20000000000000001 -0.12 0.055324999999999999 0 0 0</pose>
    </frame>
    <frame name='bl_caster_link' attached_to='bl_caster_joint'>
      <pose>0 0 0 0 0 0</pose>
    </frame>
    <frame name='br_caster_joint' attached_to='base_link'>
      <pose>-0.20000000000000001 0.12 0.055324999999999999 0 0 0</pose>
    </frame>
    <frame name='br_caster_link' attached_to='br_caster_joint'>
      <pose>0 0 0 0 0 0</pose>
    </frame>
    <frame name='estop_joint' attached_to='base_link'>
      <pose>-0.12465 0.23891999999999999 0.31126999999999999 1.5708 0 0</pose>
    </frame>
    <frame name='estop_link' attached_to='estop_joint'>
      <pose>0 0 0 0 0 0</pose>
    </frame>
    <frame name='fl_caster_joint' attached_to='base_link'>
      <pose>0.14999999999999999 0.12 0.055324999999999999 0 0 0</pose>
    </frame>
    <frame name='fl_caster_link' attached_to='fl_caster_joint'>
      <pose>0 0 0 0 0 0</pose>
    </frame>
    <frame name='fr_caster_joint' attached_to='base_link'>
      <pose>0.14999999999999999 -0.12 0.055324999999999999 0 0 0</pose>
    </frame>
    <frame name='fr_caster_link' attached_to='fr_caster_joint'>
      <pose>0 0 0 0 0 0</pose>
    </frame>
    <frame name='laser_joint' attached_to='base_link'>
      <pose>0.23499999999999999 0 0.2878 -3.1415926535895871 0 0</pose>
    </frame>
    <frame name='laser_link' attached_to='laser_joint'>
      <pose>0 0 0 0 0 0</pose>
    </frame>
    <frame name='torso_fixed_joint' attached_to='base_link'>
      <pose>-0.086874999999999994 0 0.37742500000000001 -6.12303176911189e-17 0 0</pose>
    </frame>
    <frame name='torso_fixed_link' attached_to='torso_fixed_joint'>
      <pose>0 0 0 0 0 0</pose>
    </frame>
    <frame name='bellows_joint2' attached_to='torso_lift_link'>
      <pose>0 0 0 0 0 0</pose>
    </frame>
    <frame name='bellows_link2' attached_to='bellows_joint2'>
      <pose>0 0 0 0 0 0</pose>
    </frame>
    <frame name='head_camera_depth_optical_joint' attached_to='head_camera_depth_frame'>
      <pose>0 0 0 -1.57079632679 -5.5511151231257827e-17 -1.57079632679</pose>
    </frame>
    <frame name='head_camera_depth_optical_frame' attached_to='head_camera_depth_optical_joint'>
      <pose>0 0 0 0 0 0</pose>
    </frame>
    <frame name='head_camera_depth_joint' attached_to='head_camera_link'>
      <pose>0 0.044999999999999998 0 0 0 0</pose>
    </frame>
    <frame name='head_camera_depth_frame' attached_to='head_camera_depth_joint'>
      <pose>0 0 0 0 0 0</pose>
    </frame>
    <frame name='head_camera_rgb_optical_joint' attached_to='head_camera_rgb_frame'>
      <pose>0 0 0 -1.57079632679 -5.5511151231257827e-17 -1.57079632679</pose>
    </frame>
    <frame name='head_camera_rgb_optical_frame' attached_to='head_camera_rgb_optical_joint'>
      <pose>0 0 0 0 0 0</pose>
    </frame>
    <frame name='head_camera_rgb_joint' attached_to='head_camera_link'>
      <pose>0 0.02 0 0 0 0</pose>
    </frame>
    <frame name='head_camera_rgb_frame' attached_to='head_camera_rgb_joint'>
      <pose>0 0 0 0 0 0</pose>
    </frame>
    <frame name='head_camera_joint' attached_to='head_tilt_link'>
      <pose>0.055 0 0.022499999999999999 0 0 0</pose>
    </frame>
    <frame name='head_camera_link' attached_to='head_camera_joint'>
      <pose>0 0 0 0 0 0</pose>
    </frame>
    <frame name='gripper_axis' attached_to='wrist_roll_link'>
      <pose>0.16644999999999999 0 0 0 0 0</pose>
    </frame>
    <frame name='gripper_link' attached_to='gripper_axis'>
      <pose>0 0 0 0 0 0</pose>
    </frame>
  </model>
</sdf>
